2023-08-09 00:04:04,291:INFO-bot initialized from bot_init.py
2023-08-09 00:04:21,372:INFO-Retrieving info from the database from handle_inserted_image.py line 48
2023-08-09 00:04:47,609:INFO-Asking user to enter the image with face from handle_inserted_image.py line 36
2023-08-09 00:05:05,716:ERROR-Exception occured in tele_main.py line 10
Traceback (most recent call last):
  File "D:\H_setup\fastapi-sqlalchemy-skeleton\myenv\lib\site-packages\urllib3\connectionpool.py", line 714, in urlopen
    httplib_response = self._make_request(
  File "D:\H_setup\fastapi-sqlalchemy-skeleton\myenv\lib\site-packages\urllib3\connectionpool.py", line 466, in _make_request
    six.raise_from(e, None)
  File "<string>", line 3, in raise_from
  File "D:\H_setup\fastapi-sqlalchemy-skeleton\myenv\lib\site-packages\urllib3\connectionpool.py", line 461, in _make_request
    httplib_response = conn.getresponse()
  File "C:\Users\adity\AppData\Local\Programs\Python\Python310\lib\http\client.py", line 1374, in getresponse
    response.begin()
  File "C:\Users\adity\AppData\Local\Programs\Python\Python310\lib\http\client.py", line 318, in begin
    version, status, reason = self._read_status()
  File "C:\Users\adity\AppData\Local\Programs\Python\Python310\lib\http\client.py", line 287, in _read_status
    raise RemoteDisconnected("Remote end closed connection without"
http.client.RemoteDisconnected: Remote end closed connection without response

During handling of the above exception, another exception occurred:

Traceback (most recent call last):
  File "D:\H_setup\fastapi-sqlalchemy-skeleton\myenv\lib\site-packages\requests\adapters.py", line 439, in send
    resp = conn.urlopen(
  File "D:\H_setup\fastapi-sqlalchemy-skeleton\myenv\lib\site-packages\urllib3\connectionpool.py", line 798, in urlopen
    retries = retries.increment(
  File "D:\H_setup\fastapi-sqlalchemy-skeleton\myenv\lib\site-packages\urllib3\util\retry.py", line 550, in increment
    raise six.reraise(type(error), error, _stacktrace)
  File "D:\H_setup\fastapi-sqlalchemy-skeleton\myenv\lib\site-packages\urllib3\packages\six.py", line 769, in reraise
    raise value.with_traceback(tb)
  File "D:\H_setup\fastapi-sqlalchemy-skeleton\myenv\lib\site-packages\urllib3\connectionpool.py", line 714, in urlopen
    httplib_response = self._make_request(
  File "D:\H_setup\fastapi-sqlalchemy-skeleton\myenv\lib\site-packages\urllib3\connectionpool.py", line 466, in _make_request
    six.raise_from(e, None)
  File "<string>", line 3, in raise_from
  File "D:\H_setup\fastapi-sqlalchemy-skeleton\myenv\lib\site-packages\urllib3\connectionpool.py", line 461, in _make_request
    httplib_response = conn.getresponse()
  File "C:\Users\adity\AppData\Local\Programs\Python\Python310\lib\http\client.py", line 1374, in getresponse
    response.begin()
  File "C:\Users\adity\AppData\Local\Programs\Python\Python310\lib\http\client.py", line 318, in begin
    version, status, reason = self._read_status()
  File "C:\Users\adity\AppData\Local\Programs\Python\Python310\lib\http\client.py", line 287, in _read_status
    raise RemoteDisconnected("Remote end closed connection without"
urllib3.exceptions.ProtocolError: ('Connection aborted.', RemoteDisconnected('Remote end closed connection without response'))

During handling of the above exception, another exception occurred:

Traceback (most recent call last):
  File "D:\H_setup\fastapi-sqlalchemy-skeleton\tele_bot\tele_main.py", line 8, in <module>
    main()
  File "d:\h_setup\fastapi-sqlalchemy-skeleton\tele_bot\missing_persons_functions\handle_inserted_image.py", line 118, in main
    bot.polling(True)
  File "D:\H_setup\fastapi-sqlalchemy-skeleton\myenv\lib\site-packages\telebot\__init__.py", line 1043, in polling
    self.__threaded_polling(non_stop=non_stop, interval=interval, timeout=timeout, long_polling_timeout=long_polling_timeout,
  File "D:\H_setup\fastapi-sqlalchemy-skeleton\myenv\lib\site-packages\telebot\__init__.py", line 1118, in __threaded_polling
    raise e
  File "D:\H_setup\fastapi-sqlalchemy-skeleton\myenv\lib\site-packages\telebot\__init__.py", line 1073, in __threaded_polling
    polling_thread.raise_exceptions()
  File "D:\H_setup\fastapi-sqlalchemy-skeleton\myenv\lib\site-packages\telebot\util.py", line 108, in raise_exceptions
    raise self.exception_info
  File "D:\H_setup\fastapi-sqlalchemy-skeleton\myenv\lib\site-packages\telebot\util.py", line 90, in run
    task(*args, **kwargs)
  File "D:\H_setup\fastapi-sqlalchemy-skeleton\myenv\lib\site-packages\telebot\__init__.py", line 649, in __retrieve_updates
    updates = self.get_updates(offset=(self.last_update_id + 1),
  File "D:\H_setup\fastapi-sqlalchemy-skeleton\myenv\lib\site-packages\telebot\__init__.py", line 623, in get_updates
    json_updates = apihelper.get_updates(self.token, offset, limit, timeout, allowed_updates, long_polling_timeout)
  File "D:\H_setup\fastapi-sqlalchemy-skeleton\myenv\lib\site-packages\telebot\apihelper.py", line 321, in get_updates
    return _make_request(token, method_url, params=payload)
  File "D:\H_setup\fastapi-sqlalchemy-skeleton\myenv\lib\site-packages\telebot\apihelper.py", line 156, in _make_request
    result = _get_req_session().request(
  File "D:\H_setup\fastapi-sqlalchemy-skeleton\myenv\lib\site-packages\requests\sessions.py", line 542, in request
    resp = self.send(prep, **send_kwargs)
  File "D:\H_setup\fastapi-sqlalchemy-skeleton\myenv\lib\site-packages\requests\sessions.py", line 655, in send
    r = adapter.send(request, **kwargs)
  File "D:\H_setup\fastapi-sqlalchemy-skeleton\myenv\lib\site-packages\requests\adapters.py", line 498, in send
    raise ConnectionError(err, request=request)
requests.exceptions.ConnectionError: ('Connection aborted.', RemoteDisconnected('Remote end closed connection without response'))
2023-08-09 00:06:42,902:INFO-bot initialized from bot_init.py
2023-08-09 00:06:51,769:INFO-Retrieving info from the database from handle_inserted_image.py line 48
2023-08-09 01:15:56,090:INFO-bot initialized from bot_init.py
2023-08-09 01:17:52,927:INFO-Retrieving info from the database from handle_inserted_image.py line 48
2023-08-09 01:17:52,937:ERROR-Exception occured in handle_inserted_image.py line 70
Traceback (most recent call last):
  File "d:\h_setup\fastapi-sqlalchemy-skeleton\tele_bot\missing_persons_functions\handle_inserted_image.py", line 58, in handle_inserted_image
    face_id=record[0]
TypeError: 'NoneType' object is not subscriptable
2023-08-09 01:33:04,587:INFO-bot initialized from bot_init.py
2023-08-09 01:33:17,960:INFO-Retrieving info from the database from handle_inserted_image.py line 48
2023-08-09 19:37:57,519:INFO-bot initialized from bot_init.py
2023-08-09 19:38:06,959:INFO-Asking user to enter the image with face from handle_inserted_image.py line 36
2023-08-09 19:38:07,105:INFO-Retrieving info from the database from handle_inserted_image.py line 48
2023-08-09 19:38:07,146:ERROR-Exception occured in handle_inserted_image.py line 70
Traceback (most recent call last):
  File "d:\h_setup\fastapi-sqlalchemy-skeleton\tele_bot\missing_persons_functions\handle_inserted_image.py", line 58, in handle_inserted_image
    face_id=record[0]
TypeError: 'NoneType' object is not subscriptable
2023-08-09 19:38:38,682:INFO-Retrieving info from the database from handle_inserted_image.py line 48
2023-08-09 20:07:16,705:INFO-bot initialized from bot_init.py
2023-08-09 20:07:32,564:INFO-Asking user for the person's name from handle_inserted_image.py line 40
