2023-08-18 12:32:10,049:INFO-bot initialized from bot_init.py
2023-08-18 12:32:41,887:INFO-bot initialized from bot_init.py
2023-08-18 12:33:17,247:INFO-Retrieving info from the database from handle_inserted_image.py line 48
2023-08-18 13:47:40,359:ERROR-Exception occured in tele_main.py line 10
Traceback (most recent call last):
  File "D:\H_setup\fastapi-sqlalchemy-skeleton\myenv\lib\site-packages\urllib3\connectionpool.py", line 466, in _make_request
    six.raise_from(e, None)
  File "<string>", line 3, in raise_from
  File "D:\H_setup\fastapi-sqlalchemy-skeleton\myenv\lib\site-packages\urllib3\connectionpool.py", line 461, in _make_request
    httplib_response = conn.getresponse()
  File "C:\Users\adity\AppData\Local\Programs\Python\Python310\lib\http\client.py", line 1374, in getresponse
    response.begin()
  File "C:\Users\adity\AppData\Local\Programs\Python\Python310\lib\http\client.py", line 318, in begin
    version, status, reason = self._read_status()
  File "C:\Users\adity\AppData\Local\Programs\Python\Python310\lib\http\client.py", line 279, in _read_status
    line = str(self.fp.readline(_MAXLINE + 1), "iso-8859-1")
  File "C:\Users\adity\AppData\Local\Programs\Python\Python310\lib\socket.py", line 705, in readinto
    return self._sock.recv_into(b)
  File "C:\Users\adity\AppData\Local\Programs\Python\Python310\lib\ssl.py", line 1273, in recv_into
    return self.read(nbytes, buffer)
  File "C:\Users\adity\AppData\Local\Programs\Python\Python310\lib\ssl.py", line 1129, in read
    return self._sslobj.read(len, buffer)
TimeoutError: The read operation timed out

During handling of the above exception, another exception occurred:

Traceback (most recent call last):
  File "D:\H_setup\fastapi-sqlalchemy-skeleton\myenv\lib\site-packages\requests\adapters.py", line 439, in send
    resp = conn.urlopen(
  File "D:\H_setup\fastapi-sqlalchemy-skeleton\myenv\lib\site-packages\urllib3\connectionpool.py", line 798, in urlopen
    retries = retries.increment(
  File "D:\H_setup\fastapi-sqlalchemy-skeleton\myenv\lib\site-packages\urllib3\util\retry.py", line 550, in increment
    raise six.reraise(type(error), error, _stacktrace)
  File "D:\H_setup\fastapi-sqlalchemy-skeleton\myenv\lib\site-packages\urllib3\packages\six.py", line 770, in reraise
    raise value
  File "D:\H_setup\fastapi-sqlalchemy-skeleton\myenv\lib\site-packages\urllib3\connectionpool.py", line 714, in urlopen
    httplib_response = self._make_request(
  File "D:\H_setup\fastapi-sqlalchemy-skeleton\myenv\lib\site-packages\urllib3\connectionpool.py", line 468, in _make_request
    self._raise_timeout(err=e, url=url, timeout_value=read_timeout)
  File "D:\H_setup\fastapi-sqlalchemy-skeleton\myenv\lib\site-packages\urllib3\connectionpool.py", line 357, in _raise_timeout
    raise ReadTimeoutError(
urllib3.exceptions.ReadTimeoutError: HTTPSConnectionPool(host='api.telegram.org', port=443): Read timed out. (read timeout=25)

During handling of the above exception, another exception occurred:

Traceback (most recent call last):
  File "D:\H_setup\fastapi-sqlalchemy-skeleton\tele_bot\tele_main.py", line 8, in <module>
    main()
  File "d:\h_setup\fastapi-sqlalchemy-skeleton\tele_bot\missing_persons_functions\handle_inserted_image.py", line 118, in main
    bot.polling(True)
  File "D:\H_setup\fastapi-sqlalchemy-skeleton\myenv\lib\site-packages\telebot\__init__.py", line 1043, in polling
    self.__threaded_polling(non_stop=non_stop, interval=interval, timeout=timeout, long_polling_timeout=long_polling_timeout,
  File "D:\H_setup\fastapi-sqlalchemy-skeleton\myenv\lib\site-packages\telebot\__init__.py", line 1118, in __threaded_polling
    raise e
  File "D:\H_setup\fastapi-sqlalchemy-skeleton\myenv\lib\site-packages\telebot\__init__.py", line 1073, in __threaded_polling
    polling_thread.raise_exceptions()
  File "D:\H_setup\fastapi-sqlalchemy-skeleton\myenv\lib\site-packages\telebot\util.py", line 108, in raise_exceptions
    raise self.exception_info
  File "D:\H_setup\fastapi-sqlalchemy-skeleton\myenv\lib\site-packages\telebot\util.py", line 90, in run
    task(*args, **kwargs)
  File "D:\H_setup\fastapi-sqlalchemy-skeleton\myenv\lib\site-packages\telebot\__init__.py", line 649, in __retrieve_updates
    updates = self.get_updates(offset=(self.last_update_id + 1),
  File "D:\H_setup\fastapi-sqlalchemy-skeleton\myenv\lib\site-packages\telebot\__init__.py", line 623, in get_updates
    json_updates = apihelper.get_updates(self.token, offset, limit, timeout, allowed_updates, long_polling_timeout)
  File "D:\H_setup\fastapi-sqlalchemy-skeleton\myenv\lib\site-packages\telebot\apihelper.py", line 321, in get_updates
    return _make_request(token, method_url, params=payload)
  File "D:\H_setup\fastapi-sqlalchemy-skeleton\myenv\lib\site-packages\telebot\apihelper.py", line 156, in _make_request
    result = _get_req_session().request(
  File "D:\H_setup\fastapi-sqlalchemy-skeleton\myenv\lib\site-packages\requests\sessions.py", line 542, in request
    resp = self.send(prep, **send_kwargs)
  File "D:\H_setup\fastapi-sqlalchemy-skeleton\myenv\lib\site-packages\requests\sessions.py", line 655, in send
    r = adapter.send(request, **kwargs)
  File "D:\H_setup\fastapi-sqlalchemy-skeleton\myenv\lib\site-packages\requests\adapters.py", line 529, in send
    raise ReadTimeout(e, request=request)
requests.exceptions.ReadTimeout: HTTPSConnectionPool(host='api.telegram.org', port=443): Read timed out. (read timeout=25)
2023-08-18 14:44:50,642:INFO-bot initialized from bot_init.py
